Workbook

Sheet Readme
A1: Description
A2: Date for creation of this file: 20th February 2024
A4: This excel sheet includes data on GHG intensities obtained with EXIOBASE v3.8-beta1 hybrid
A6: Database | B6: EXIOBASE v3.8-beta1 hybrid
B7: Date EXIOBASE version: 30th June 2023
B8: Webpage: https://lca.aau.dk/
B9: Exiobase v3.8-beta1 hybrid has been created as part of: https://lca-net.com/clubs/exiobase-update/. The development of the workflow and IPCC models are obtained from: https://www.en.plan.aau.dk/research/the-danish-centre-for-environmental-assessment/getting-the-data-right
B10: Year: 2016
A12: Methods | B12: > All GHG intensities in this file are presented as tonne CO2-eq. per unit (the uit is specified in column D in the GHG intensity sheets)
B13: > Land use changes: iLUC is modelled using the iLUC model version 4.3 (https://lca-net.com/clubs/iluc/). The framework of the model is described here: Schmidt J, Weidema B P, Brandão M (2015). A framework for modelling indirect land use changes in life cycle assessment. Journal of Cleaner Production 99:230‑238
B14: The implmentation of the iLUC model in EXIOBASE is described here: Schmidt J, De Rosa M (2018). Enhancing Land Use Change modelling with IO data. Presentation at the SETAC Europe 28th Annual Meeting, Rome, 13-17 May 2018. https://lca-net.com/p/3036
B15: > Electricity model: The electricity model is using the method described here: Muñoz I, Schmidt J, de Saxcé M, Dalgaard R, Merciai S (2015). Inventory of country specific electricity in LCA – consequential scenarios. Version 3.0. Report of the 2.-0 LCA Energy Club. 2.-0 LCA consultants, Aalborg https://lca-net.com/p/3935
B16: This model is implemented in EXIOBASE following the methods described here: Merciai S and Schmidt J (2017). Land use change and electricity models in a multi-regional hybrid input output framework. Paper 25th IIOA Conference in Atlantic City, 19-23 June 2017, USA. https://lca-net.com/p/4513
B17: > Investments: It should be noted that investments, which are typically kept as a final demand category in IO-tables, are integrated in the core IO-table. This corresponds to including capital goods in LCA.
B18: > LCIA method: GHG emissions are calculated using IPCC (2013), i.e. the characterisation factors for CH4 biogenic, CH4 fossil and N2O are: 27.75 kg CO2-eq/kg, 30.5 kg CO2.eq/kg and 265 kg CO2-eq/kg respectively.
B19: On the difference between CH4 from biogenic vs. fossil sources see Muñoz I, Schmidt J (2016). Methane oxidation, biogenic carbon, and the IPCC’s emission metrics. Proposal for a consistent greenhouse-gas accounting. International Journal of Life Cycle Assessment 21:1069–1075
A21: License | B21: https://www.exiobase.eu/index.php/terms-of-use
A23: Data are extracted and provided by 2.-0 LCA consultants
B24: Stefano Merciai
B25: Jannick Schmidt
B26: Valentin Starlinger
A29: Description of the sheets in this excel sheet
B30: GHG production - hybrid | C30: Products at producer (basic price): GHG emissions (tonne CO2-eq.) per unit (units are specified in column D)
B31: GHG market_hybrid | C31: Products at market (basic price*): GHG emissions (tonne CO2-eq.) per unit (units are specified in column D)
B32: GHG market_monetary | C32: Products at market (purchasers price): GHG emissions (tonne CO2-eq.) per MEUR2016
C33: * the product markets in hybrid units are currently provided per basic prices, i.e. inputs of transport and trade margins and product taxes are currently not included. This will be included in the next version.
A35: Country abbreviations
B36: Austria | C36: AT
B37: Australia | C37: AU
B38: Belgium | C38: BE
B39: Bulgaria | C39: BG
B40: Brazil | C40: BR
B41: Canada | C41: CA
B42: Switzerland | C42: CH
B43: China | C43: CN
B44: Cyprus | C44: CY
B45: CzechRepublic | C45: CZ
B46: Germany | C46: DE
B47: Denmark | C47: DK
... B83: RoW Middle East | C83: WM

Sheet GHG production - hybrid
A1: GHG intensities: tonne CO2-eq. per unit
A2: No | B2: EXIOBASE product code | C2: Nace rev1 code | D2: Nace rev2 code | E2: Description | F2: Unit | G2: AT | H2: AU | I2: BE | J2: BG | K2: BR | L2: CA | M2: CH | N2: CN | O2: CY | P2: CZ | Q2: DE | R2: DK | S2: EE | T2: ES | U2: FI | V2: FR | W2: GB | X2: GR | Y2: Global | Z2: HR | AA2: HU | AB2: ID | AC2: IE | AD2: IN | AE2: IT | AF2: JP | AG2: KR | AH2: LT | AI2: LU | AJ2: LV | AK2: MT | AL2: MX | AM2: NL | AN2: NO | AO2: PL | AP2: PT | AQ2: RO | AR2: RU | AS2: SE | AT2: SI | AU2: SK | AV2: TR | AW2: TW | AX2: US | AY2: WA | AZ2: WE | BA2: WF | BB2: WL | BC2: WM | BD2: ZA
A3: 1 | B3: A_Ricey | C3: 01.a | D3: 01.12 | E3: Rice, paddy | F3: tonnes | H3: 1.6835463 | J3: 2.5416114 | K3: 1.8238444 | N3: 2.7750217 | T3: 1.9451067 | V3: 2.9573407 | X3: 1.4806261 | AA3: 3.3970557 | AB3: 2.8331631 | AD3: 2.92581 | AE3: 2.4153112 | AF3: 2.8048108 | AG3: 2.4831094 | AL3: 1.8897061 | AP3: 2.3485249 | AQ3: 3.1466578 | AR3: 2.9874298 | AV3: 2.013476 | AW3: 0.25796814 | AX3: 2.1455835 | AY3: 2.5470732 | AZ3: 3.1357905 | BA3: 2.8487079 | BB3: 2.7146871 | BC3: 2.3546642 | BD3: 5.3670517
A4: 2 | B4: A_Germt | C4: 01.b | D4: 01.11 | E4: Germ, wheat | F4: tonnes | G4: 0.31305153 | H4: 0.5963983 | I4: 0.5100138 | J4: 5.5544416 | L4: 0.63287242 | M4: 0.078950728 | N4: 0.47784702 | P4: 0.42436935 | Q4: 0.091454024 | R4: 0.47913582 | S4: 0.36881215 | U4: 0.30928218 | V4: 0.63555972 | W4: 1.859407 | X4: 0.067564321 | Z4: 0.31847515 | AA4: 0.4324414 | AB4: 0.06519764 | AD4: 0.21673568 | AE4: 0.77982362 | AH4: 0.25518267 | AI4: 0.71527125 | AJ4: 0.37326971 | AK4: 1.2905931 | AL4: 0.46017257 | AM4: 1.0199355 | AN4: 0.4202087 | AO4: 1.1798221 | AP4: 0.55251887 | AQ4: 0.21177208 | AT4: 0.53051063 | AU4: 0.39016231 | AV4: 0.38704371 | AW4: 0.080091649 | AY4: 0.23602916 | AZ4: 1.7221771 | BA4: 0.17931421 | BB4: 12.101768 | BC4: 0.55018917 | BD4: 0.80375356
A5: 3 | B5: A_Wheat | C5: 01.b | D5: 01.11 | E5: Wheat | F5: tonnes | G5: 1.0158941 | H5: 1.5706298 | I5: 1.0550358 | J5: 1.0819611 | K5: 2.2115047 | L5: 1.3301612 | M5: 1.4016494 | N5: 1.6635407 | O5: 6.1007307 | P5: 1.0867337 | Q5: 0.89655488 | R5: 0.89346551 | S5: 1.9011236 | T5: 1.0600968 | U5: 1.4720206 | V5: 1.2158198 | W5: 1.0602858 | X5: 1.1083778 | Z5: 1.0620761 | AA5: 0.90607301 | AC5: 0.75906046 | AD5: 1.1733537 | AE5: 1.4673143 | AF5: 2.2199265 | AG5: 2.9518287 | AH5: 1.2008405 | AI5: 1.2342033 | AJ5: 1.5599049 | AK5: 1.0023983 | AL5: 1.2034598 | AM5: 0.96432676 | AN5: 1.2853748 | AO5: 1.2355217 | AP5: 2.1627005 | AQ5: 1.0017564 | AR5: 1.5636974 | AS5: 1.087857 | AT5: 1.2328978 | AU5: 0.96987868 | AV5: 1.3305209 | AW5: 0.43768903 | AX5: 1.4950269 | AY5: 1.684082 | AZ5: 1.3875875 | BA5: 0.96049038 | BB5: 1.4271157 | BC5: 0.85510963 | BD5: 1.2050141
A6: 4 | B6: A_Barly | C6: 01.c | D6: 01.11 | E6: Barley | F6: tonnes | G6: 0.89899706 | H6: 1.4127067 | I6: 0.97296628 | J6: 0.8823726 | K6: 1.2155577 | L6: 1.221067 | M6: 1.1549523 | N6: 1.9735238 | O6: 27.303776 | P6: 1.1976576 | Q6: 0.87369142 | R6: 0.93195472 | S6: 2.0444894 | T6: 1.1149706 | U6: 1.6781558 | V6: 1.1180305 | W6: 0.93329819 | X6: 0.9168824 | Z6: 1.2433907 | AA6: 0.97144085 | AC6: 0.82049638 | AD6: 1.1305888 | AE6: 1.850449 | AF6: 3.303923 | AG6: 4.9373372 | AH6: 1.5033846 | AI6: 1.5479304 | AJ6: 2.3766655 | AK6: 1.1608903 | AL6: 2.1732905 | AM6: 1.2635867 | AN6: 1.3847448 | AO6: 1.6246124 | AP6: 2.4932435 | AQ6: 0.95502515 | AR6: 1.5093343 | AS6: 1.1361303 | AT6: 1.427817 | AU6: 1.0526354 | AV6: 1.2585613 | AX6: 1.185371 | AY6: 1.0065297 | AZ6: 1.3843303 | BA6: 0.79264041 | BB6: 0.95849923 | BC6: 1.0627825 | BD6: 1.0534656
A7: 5 | B7: A_Buckt | C7: 01.c | D7: 01.11 | E7: Buckwheat | F7: tonnes | K7: 4.0674208 | L7: 5.7591317 | N7: 7.3427042 | P7: 2.3674473 | S7: 4.6345311 | V7: 1.9362754 | Z7: 4.0208896 | AA7: 2.7451907 | AF7: 14.444259 | AG7: 15.520316 | AH7: 3.6462958 | AJ7: 4.7224884 | AO7: 3.3806927 | AR7: 2.6699547 | AT7: 5.5801454 | AU7: 3.6963602 | AX7: 3.8175678 | AY7: 3.2242016 | AZ7: 3.7216892 | BA7: 0.63133218 | BD7: 7.400577
A8: 6 | B8: A_Ceres | C8: 01.c | D8: 01.11 | E8: Cereals nes | F8: tonnes | G8: 0.7581836 | J8: 1.1709949 | M8: 1.2545403 | N8: 1.0512789 | P8: 1.8317571 | T8: 1.0317493 | U8: 1.8908809 | V8: 0.9111749 | X8: 0.67622691 | Z8: 1.0123985 | AA8: 0.85019431 | AC8: 1.5442021 | AE8: 1.0120593 | AG8: 2.0398257 | AH8: 3.1094474 | AI8: 0.88630423 | AL8: 1.7069821 | AO8: 2.4242201 | AQ8: 1.294674 | AR8: 3.2196856 | AT8: 0.78903095 | AU8: 2.7064776 | AW8: 0.00405261 | AY8: 0.33808187 | AZ8: 1.1552352 | BA8: 0.34514706 | BB8: 1.863225 | BC8: 0.67493639 | BD8: 2.87495
A9: 7 | B9: A_Fonio | C9: 01.c | D9: 01.29 | E9: Fonio | F9: tonnes | BA9: 0.73777327
A10: 8 | B10: A_Germe | C10: 01.c | D10: 01.19 | E10: Germ, maize | F10: tonnes | G10: 0.13474685 | H10: 0.27855964 | I10: 0.25653074 | J10: 0.090897451 | K10: 0.081852026 | L10: 0.24100217 | M10: 0.13992504 | N10: 0.26482589 | P10: 0.190177 | Q10: 0.020620239 | R10: 0.17088832 | S10: 0.14033322 | T10: 0.21525299 | V10: 0.16831849 | W10: 0.095049486 | X10: 0.035925701 | Z10: 0.16503327 | AA10: 0.15609013 | AB10: 0.097884761 | AC10: 0.14233831 | AD10: 0.17381903 | AE10: 0.36823297 | AF10: 0.93099884 | AG10: 0.36137993 | AI10: 0.39788865 | AL10: 0.20733822 | AM10: 0.49479114 | AO10: 0.28033881 | AP10: 0.2875305 | AQ10: 0.091671947 | AR10: 0.22661518 | AT10: 0.23104698 | AU10: 0.089363713 | AV10: 0.20931038 | AW10: 0.003796279 | AX10: 0.12902104 | AY10: 0.16077272 | AZ10: 0.1158057 | BA10: 0.04896206 | BB10: 0.19678793 | BC10: 0.37280586 | BD10: 0.38419237
A11: 9 | B11: A_Graid | C11: 01.c | D11: 01.11 | E11: Grain, mixed | F11: tonnes | G11: 1.4245817 | I11: 2.2833932 | L11: 1.5959109 | M11: 1.3888519 | P11: 1.9780996 | Q11: 1.545814 | R11: 1.3180183 | S11: 2.3820904 | T11: 2.0259459 | U11: 2.2803206 | V11: 1.8323745 | W11: 0.98182083 | X11: 1.0516042 | Z11: 2.0517847 | AH11: 2.1900199 | AI11: 1.6195268 | AJ11: 4.5676422 | AO11: 2.0808295 | AS11: 1.6982206 | AT11: 1.7502795 | AV11: 1.879883 | AY11: 0.30968825 | AZ11: 1.7537997
A12: 10 | B12: A_Hops | C12: 01.c | D12: 01.28 | E12: Hops | F12: tonnes | G12: 2.2808578 | H12: 3.3236086 | I12: 2.4550339 | J12: 3.0277805 | M12: 2.5018215 | N12: 4.3808676 | P12: 4.6084639 | Q12: 2.3457835 | T12: 1.8802939 | V12: 2.401673 | W12: 1.5176245 | AC12: 3.6971892 | AF12: 4.641288 | AO12: 2.845321 | AP12: 2.0513612 | AQ12: 3.0803559 | AR12: 4.2003442 | AT12: 2.8449703 | AU12: 2.5638225 | AX12: 2.9702254 | AY12: 6.5166172 | AZ12: 6.8413129 | BA12: 1.010452 | BB12: 2.6120801 | BD12: 5.0609295
A13: 11 | B13: A_Maize | C13: 01.c | D13: 01.11 | E13: Maize | F13: tonnes | G13: 0.44499803 | H13: 0.39871261 | I13: 0.50860852 | J13: 1.0445062 | K13: 1.3025598 | L13: 0.5647714 | M13: 0.71425898 | N13: 1.0637186 | P13: 0.69443414 | Q13: 0.63095436 | R13: 0.57881045 | T13: 0.28991091 | V13: 0.73727147 | X13: 0.25124159 | Z13: 0.60679881 | AA13: 0.49163581 | AB13: 1.170071 | AD13: 1.1472343 | AE13: 0.58557063 | AF13: 2.7545454 | AG13: 2.3688858 | AH13: 0.69122936 | AI13: 0.89591725 | AL13: 1.3027345 | AM13: 0.634765 | AO13: 0.72396803 | AP13: 0.63845058 | AQ13: 0.74456349 | AR13: 0.70086529 | AT13: 0.64078941 | AU13: 0.55009685 | AV13: 0.53353668 | AW13: 0.011809271 | AX13: 0.54769838 | AY13: 0.66301015 | AZ13: 0.75288081 | BA13: 0.64399872 | BB13: 0.72113396 | BC13: 0.5198617 | BD13: 0.87090244
A14: 12 | B14: A_Maizn | C14: 01.c | D14: 01.11 | E14: Maize, green | F14: tonnes | G14: 0.51243403 | H14: 0.56144915 | J14: 0.73187634 | L14: 0.75303668 | M14: 1.867575 | N14: 1.8575192 | V14: 0.54145053 | X14: 0.20510721 | Z14: 0.43187487 | AA14: 0.47900765 | AB14: 1.1984902 | AF14: 1.9193448 | AL14: 0.64024565 | AN14: 1.1762774 | AO14: 0.68701563 | AQ14: 0.95672361 | AU14: 0.55297616 | AX14: 0.507278 | AY14: 1.00273 | AZ14: 0.49643021 | BA14: 0.45367571 | BB14: 0.5495202 | BC14: 0.71866882 | BD14: 0.88841251
A15: 13 | B15: A_Millt | C15: 01.c | D15: 01.11 | E15: Millet | F15: tonnes | G15: 0.98652121 | H15: 1.9792628 | J15: 2.0157205 | M15: 2.5614814 | N15: 2.1748921 | P15: 4.3413213 | T15: 1.1842634 | V15: 1.6700558 | X15: 0.87614921 | Z15: 2.9083428 | AA15: 1.9110035 | AD15: 2.0034801 | AF15: 8.4489779 | AG15: 7.776312 | AL15: 2.9994061 | AO15: 2.2454809 | AR15: 1.6482232 | AT15: 2.8962664 | AU15: 2.1118269 | AV15: 1.2412715 | AW15: 0.015338158 | AX15: 1.0695428 | AY15: 1.5609403 | AZ15: 2.1280036 | BA15: 0.92011329 | BB15: 1.6649592 | BC15: 2.3204272 | BD15: 4.7808463
A16: 14 | B16: A_Mushs | C16: 01.c | D16: 01.13 | E16: Mushrooms and truffles | F16: tonnes | G16: 0.24783209 | H16: 0.69895078 | I16: 0.39519699 | J16: 0.30498055 | L16: 0.58867666 | M16: 0.65828128 | N16: 0.67387846 | O16: 1.4185048 | P16: 0.64090546 | Q16: 0.21205906 | R16: 0.62716685 | T16: 0.33639326 | U16: 1.827661 | V16: 0.24312877 | W16: 0.18216872 | X16: 0.36171447 | AA16: 0.222718 | AB16: 0.15901673 | AC16: 0.27359235 | AD16: 0.36382057 | AE16: 1.1882888 | AF16: 1.0031903 | AG16: 0.4838874 | AH16: 0.2264364 | AI16: 1.5011617 | AJ16: 0.20876039 | AK16: 1.9433845 | AM16: 0.68255222 | AO16: 0.40949356 | AP16: 0.68827798 | AQ16: 0.19490291 | AR16: 3.5122167 | AU16: 0.33322075 | AV16: 0.33157168 | AW16: 0.008144248 | AX16: 0.19065716 | AY16: 0.52086665 | AZ16: 0.28079595 | BA16: 0.6849349 | BC16: 1.5848043 | BD16: 0.64640004
A17: 15 | B17: A_Oatss | C17: 01.c | D17: 01.11 | E17: Oats | F17: tonnes | G17: 0.96085381 | H17: 1.5943332 | I17: 0.97337425 | J17: 1.6928572 | K17: 1.7481866 | L17: 1.1165231 | M17: 1.405244 | N17: 1.6781754 | O17: 5.8183011 | P17: 1.5596403 | Q17: 1.0720653 | R17: 0.81762992 | S17: 2.0696583 | T17: 1.4316973 | U17: 1.4359457 | V17: 1.0458681 | W17: 0.81424269 | X17: 1.0370686 | Z17: 1.446278 | AA17: 1.2858545 | AC17: 0.59251754 | AE17: 2.1359891 | AF17: 3.1489531 | AH17: 1.9035581 | AI17: 1.0782137 | AJ17: 2.5290544 | AL17: 2.5446326 | AM17: 1.0373633 | AN17: 1.0672253 | AO17: 1.8401383 | AP17: 2.7581323 | AQ17: 1.3231208 | AR17: 1.585374 | AS17: 1.0899427 | AT17: 1.5389942 | AU17: 1.636274 | AV17: 1.1400184 | AX17: 1.4530724 | AY17: 0.9814956 | AZ17: 1.8636639 | BA17: 0.59398521 | BB17: 1.1581133 | BC17: 3.7284634 | BD17: 1.6215587
A18: 16 | B18: A_Poppd | C18: 01.c | D18: 01.11 | E18: Poppy seed | F18: tonnes | G18: 4.7209697 | J18: 3.9363762 | P18: 5.2230868 | Q18: 7.0597624 | T18: 2.5019518 | V18: 4.3090725 | Z18: 3.8838064 | AA18: 3.5513765 | AM18: 4.8759873 | AQ18: 5.4298774 | AU18: 3.6371794 | AV18: 3.8430714 | AZ18: 4.0601268 | BC18: 1.0488131
A19: 17 | B19: A_Quina | C19: 01.c | D19: 01.11 | E19: Quinoa | F19: tonnes | BB19: 3.5709595
A20: 18 | B20: A_Ryee | C20: 01.c | D20: 01.11 | E20: Rye | F20: tonnes | G20: 0.76780763 | H20: 3.7112335 | I20: 1.2622164 | J20: 1.5683942 | K20: 2.8865676 | L20: 0.90338784 | M20: 1.2941089 | N20: 1.174409 | P20: 1.0591514 | Q20: 0.85342902 | R20: 0.68518205 | S20: 1.6648294 | T20: 1.3278074 | U20: 1.4232904 | V20: 1.3473251 | W20: 2.343954 | X20: 1.0258756 | Z20: 1.2385606 | AA20: 1.156921 | AC20: 1.3497808 | AE20: 1.5935075 | AG20: 5.0663692 | AH20: 1.6938246 | AI20: 1.0762495 | AJ20: 1.4341063 | AL20: 3.8006533 | AM20: 1.2677508 | AN20: 0.92481362 | AO20: 1.5134129 | AP20: 4.8212748 | AQ20: 1.159266 | AR20: 1.220755 | AS20: 0.78622919 | AT20: 1.2479528 | AU20: 1.1428017 | AV20: 0.95708275 | AX20: 1.9190777 | AY20: 1.4114616 | AZ20: 2.0404893 | BA20: 0.87539411 | BB20: 2.0032279 | BC20: 0.96258241 | BD20: 2.2884193
A21: 19 | B21: A_Sorgm | C21: 01.c | D21: 01.11 | E21: Sorghum | F21: tonnes | G21: 0.60662086 | H21: 0.97449152 | J21: 1.3612259 | K21: 2.4602849 | N21: 1.2442087 | T21: 0.76314253 | V21: 0.83432121 | X21: 0.87137743 | Z21: 2.5010815 | AA21: 0.92149909 | AD21: 3.2566168 | AE21: 0.93081489 | AG21: 5.4765329 | AL21: 1.5899838 | AQ21: 0.91496615 | AR21: 1.6451113 | AU21: 1.475055 | AV21: 0.99918419 | AW21: 0.010756127 | AX21: 1.0100739 | AY21: 1.5496188 | AZ21: 0.99947916 | BA21: 0.67949733 | BB21: 1.1024008 | BC21: 1.0145184 | BD21: 1.9088948
A22: 20 | B22: A_Trite | C22: 01.c | D22: 01.11 | E22: Triticale | F22: tonnes | G22: 0.98283601 | H22: 1.7983672 | I22: 1.1249117 | J22: 1.0861399 | K22: 1.9437693 | L22: 1.2801775 | M22: 1.3096407 | N22: 2.5031481 | P22: 1.3147799 | Q22: 0.84178535 | R22: 0.92811737 | S22: 1.5554779 | T22: 1.4433016 | V22: 1.0486494 | W22: 1.1439157 | X22: 0.96110096 | Z22: 1.1918899 | AA22: 1.043772 | AE22: 1.3424884 | AH22: 1.3214181 | AI22: 1.3999026 | AJ22: 1.8566197 | AL22: 1.6392117 | AM22: 1.3757926 | AO22: 1.479695 | AP22: 2.9508768 | AQ22: 0.8830897 | AR22: 1.0439639 | AS22: 1.0520392 | AT22: 1.2495428 | AU22: 1.124256 | AV22: 0.9591728 | AY22: 0.90403937 | AZ22: 1.9228022 | BA22: 0.34601534 | BB22: 0.69624016
A23: 21 | B23: A_Almol | C23: 01.d | D23: 01.25 | E23: Almonds, with shell | F23: tonnes | H23: 1.4014871 | J23: 4.4885108 | N23: 2.3754537 | O23: 23.984564 | T23: 7.2356956 | V23: 4.0525128 | X23: 1.0129926 | Z23: 6.4860488 | AA23: 5.8020351 | AE23: 3.1668748 | AL23: 2.5876676 | AP23: 11.02374 | AT23: 8.6085988 | AV23: 1.4653028 | AX23: 1.2765559 | AY23: 1.8597224 | AZ23: 2.5301972 | BA23: 3.2543657 | BB23: 2.0390894 | BC23: 1.6912087
A24: 22 | B24: A_Anisr | C24: 01.d | D24: 01.28 | E24: Anise, badian, fennel, coriander | F24: tonnes | H24: 6.8625532 | J24: 4.9526581 | L24: 5.0020591 | N24: 7.0385094 | R24: 8.5914327 | T24: 3.9063568 | X24: 2.2297088 | AA24: 2.5242361 | AD24: 3.2137556 | AH24: 3.7041852 | AL24: 0.71765311 | AM24: 4.0842025 | AQ24: 2.0572997 | AR24: 4.6770775 | AU24: 3.1378561 | AV24: 6.6343216 | AY24: 5.7969311 | AZ24: 4.3093128 | BA24: 1.2108951 | BB24: 3.5830762 | BC24: 2.218139
A25: 23 | B25: A_Appls | C25: 01.d | D25: 01.22 | E25: Apples | F25: tonnes | G25: 0.10521374 | H25: 0.73274228 | I25: 0.36004453 | J25: 0.49462153 | K25: 0.2723925 | L25: 0.39899317 | M25: 0.34010221 | N25: 0.64079045 | O25: 1.0839377 | P25: 0.46342656 | Q25: 0.21480538 | R25: 0.33257781 | S25: 1.7730803 | T25: 0.31787769 | U25: 0.76296509 | V25: 0.31907019 | W25: 0.26763473 | X25: 0.1895325 | Z25: 0.70418871 | AA25: 0.34988868 | AC25: 0.41058206 | AD25: 0.35663854 | AE25: 0.43942103 | AF25: 1.2684399 | AG25: 0.7502713 | AH25: 0.72667069 | AI25: 1.4946405 | AJ25: 1.2804679 | AK25: 0.82833108 | AL25: 0.67635755 | AM25: 0.66895996 | AN25: 1.058485 | AO25: 0.41611842 | AP25: 0.61288661 | AQ25: 0.42769601 | AR25: 0.49730918 | AS25: 0.40641752 | AT25: 0.43240714 | AU25: 0.46684623 | AV25: 0.40674145 | AW25: 0.01195996 | AX25: 0.34088852 | AY25: 0.56363744 | AZ25: 0.45677349 | BA25: 0.37552899 | BB25: 0.7267016 | BC25: 0.42037716 | BD25: 1.0345263
A26: 24 | B26: A_Apris | C26: 01.d | D26: 01.24 | E26: Apricots | F26: tonnes | G26: 0.86027778 | H26: 2.5317203 | J26: 0.77719932 | L26: 0.69566335 | M26: 0.61158976 | N26: 3.264977 | O26: 1.5818198 | P26: 6.3061089 | Q26: 1.1122031 | T26: 0.57401314 | V26: 0.30602464 | X26: 0.27694605 | Z26: 1.9115231 | AA26: 0.77982149 | AD26: 1.1604467 | AE26: 0.67761679 | AF26: 2.2569039 | AK26: 0.61887821 | AL26: 1.2949622 | AO26: 1.6511938 | AP26: 1.185752 | AQ26: 0.31287249 | AR26: 0.61152025 | AT26: 0.5624773 | AU26: 2.3135959 | AV26: 0.79120032 | AW26: 0.01287192 | AX26: 0.60894446 | AY26: 0.72593954 | AZ26: 0.59556168 | BA26: 0.42747163 | BB26: 0.96941423 | BC26: 0.60245541 | BD26: 1.3578906
A27: 25 | B27: A_Arecs | C27: 01.d | D27: 01.25 | E27: Areca nuts | F27: tonnes | AB27: 10.028466 | AD27: 1.7562436 | AW27: 0.01592993 | AY27: 2.8983561
A28: 26 | B28: A_Artis | C28: 01.d | D28: 01.13 | E28: Artichokes | F28: tonnes | M28: 6.8135004 | N28: 2.557272 | O28: 0.43968492 | T28: 0.29957394 | V28: 1.0287362 | X28: 0.37656684 | AE28: 0.72039633 | AH28: 0.42763218 | AK28: 0.35029665 | AL28: 0.67920971 | AQ28: 0.30699922 | AV28: 0.60377992 | AX28: 0.46716795 | AY28: 0.37325535 | BA28: 0.14236938 | BB28: 0.78175358 | BC28: 0.26685196
A29: 27 | B29: A_Aspas | C29: 01.d | D29: 01.13 | E29: Asparagus | F29: tonnes | G29: 1.7529745 | H29: 1.1271144 | I29: 0.77971551 | J29: 0.99424536 | L29: 1.0217904 | M29: 3.7672536 | N29: 1.9072446 | P29: 2.0872985 | Q29: 1.3321939 | R29: 2.5097727 | T29: 0.73576934 | U29: 9.9884098 | V29: 1.3839301 | W29: 2.642839 | X29: 0.66501349 | AA29: 1.0005048 | AE29: 0.94817498 | AF29: 2.1879735 | AH29: 0.76883313 | AL29: 0.80959283 | AM29: 1.6689279 | AO29: 0.80917114 | AT29: 1.5522767 | AU29: 1.2687256 | AV29: 1.4537214 | AW29: 0.019470391 | AX29: 1.5467269 | AY29: 0.63161828 | AZ29: 1.2833056 | BA29: 0.2731771 | BB29: 0.84940025 | BC29: 0.58908423 | BD29: 1.0603829
A30: 28 | B30: A_Avocs | C30: 01.d | D30: 01.22 | E30: Avocados | F30: tonnes | H30: 1.4175468 | K30: 0.45756791 | N30: 2.06172 | O30: 1.060977 | T30: 0.6146006 | V30: 0.78573033 | X30: 0.54201191 | AB30: 0.57523914 | AL30: 1.02052 | AV30: 1.1415041 | AX30: 1.3218736 | AY30: 0.85709621 | AZ30: 1.5083695 | BA30: 0.41463669 | BB30: 0.97116465 | BC30: 0.69674409 | BD30: 1.6371209
A31: 29 | B31: A_Bambs | C31: 01.d | D31: 01.25 | E31: Bambara beans | F31: tonnes | BA31: 1.0026368
A32: 30 | B32: A_Banas | C32: 01.d | D32: 01.22 | E32: Bananas | F32: tonnes | H32: 0.66748959 | K32: 0.4942036 | N32: 0.73994839 | O32: 0.75600757 | T32: 0.26087235 | X32: 0.19889412 | AB32: 0.17522361 | AD32: 0.21953292 | AE32: 0.55554385 | AF32: 2.7955897 | AL32: 0.47142492 | AP32: 0.52781481 | AV32: 0.308418 | AW32: 0.014595514 | AX32: 0.6163705 | AY32: 0.34279993 | BA32: 0.35687435 | BB32: 0.42220557 | BC32: 0.41460094 | BD32: 1.0220347
A33: 31 | B33: A_Beann | C33: 01.d | D33: 01.25 | E33: Beans, green | F33: tonnes | G33: 0.29413745 | H33: 0.97166425 | I33: 0.5122089 | J33: 0.40216524 | L33: 0.5977879 | M33: 0.6614645 | N33: 0.27987276 | O33: 0.23676571 | P33: 1.9135718 | Q33: 0.40276295 | T33: 0.2391732 | U33: 1.8916992 | V33: 1.116575 | W33: 0.55933738 | X33: 0.35162551 | Z33: 1.0838057 | AA33: 0.30938892 | AB33: 0.59894554 | AC33: 0.71519664 | AD33: 0.88809388 | AE33: 0.52866883 | AH33: 0.99720969 | AI33: 2.6447731 | AL33: 0.40670928 | AM33: 0.98594025 | AN33: 0.9107746 | AO33: 0.34094271 | AP33: 0.51468701 | AQ33: 0.44915119 | AT33: 0.73466477 | AU33: 5.4371664 | AV33: 0.24215576 | AW33: 0.014803221 | AX33: 1.3296093 | AY33: 0.2953289 | AZ33: 1.6887253 | BA33: 0.13087105 | BB33: 0.96960255 | BC33: 0.29959441 | BD33: 1.0769279
A34: 32 | B34: A_Beany | C34: 01.d | D34: 01.25 | E34: Beans, dry | F34: tonnes | H34: 3.7970497 | I34: 1.4008768 | J34: 2.424865 | K34: 3.3127233 | L34: 2.0010848 | N34: 1.9427868 | O34: 1.6535701 | S34: 1.4936347 | T34: 2.0172167 | V34: 3.5000421 | X34: 1.3037065 | Z34: 3.9612014 | AA34: 1.7515279 | AB34: 3.7059512 | AD34: 5.0317338 | AE34: 2.5336898 | AF34: 3.9067863 | AG34: 4.0423458 | AH34: 1.1335493 | AJ34: 1.4629383 | AK34: 1.04559 | AL34: 4.3585647 | AM34: 1.6541194 | AO34: 1.7926337 | AP34: 4.883273 | AQ34: 2.0523072 | AR34: 1.3209164 | AT34: 2.4861178 | AU34: 1.9931612 | AV34: 1.0125904 | AW34: 0.11117788 | AX34: 2.2786509 | AY34: 0.73876917 | AZ34: 1.658774 | BA34: 0.63636175 | BB34: 3.1869649 | BC34: 0.88455064 | BD34: 3.1683083
A35: 33 | B35: A_Berrs | C35: 01.d | D35: 01.25 | E35: Berries nes | F35: tonnes | G35: 0.99421916 | H35: 1.6286171 | I35: 1.2697385 | J35: 3.3861357 | M35: 1.4136058 | N35: 1.3001406 | P35: 2.6519918 | Q35: 1.90605 | S35: 10.25015 | T35: 0.60078034 | U35: 5.3163685 | W35: 0.54265398 | X35: 0.86864404 | Z35: 5.0667859 | AC35: 1.5577426 | AD35: 0.56285724 | AE35: 0.90701933 | AH35: 3.9218419 | AJ35: 4.3616093 | AK35: 1.183854 | AL35: 0.54827465 | AM35: 1.5225477 | AN35: 2.1494696 | AO35: 1.2382582 | AP35: 0.47723374 | AQ35: 0.44834676 | AR35: 0.75123926 | AS35: 4.517985 | AT35: 1.253472 | AU35: 0.58869863 | AV35: 0.76977514 | AX35: 0.73632476 | AY35: 0.73934301 | AZ35: 1.6297755 | BA35: 0.51835355 | BB35: 2.176964 | BC35: 0.95769812 | BD35: 1.5873471
A36: 34 | B36: A_Blues | C36: 01.d | D36: 01.25 | E36: Blueberries | F36: tonnes | H36: 1.2134059 | J36: 0.61896826 | L36: 0.82552157 | M36: 1.2829942 | Q36: 1.5466234 | R36: 7.1075523 | T36: 0.45525162 | V36: 1.8082176 | AE36: 0.84127717 | AH36: 2.8788175 | AJ36: 3.1910373 | AL36: 0.70736733 | AM36: 2.7583851 | AN36: 9.2026448 | AO36: 2.1298812 | AP36: 0.76502722 | AQ36: 1.1833274 | AR36: 0.57378541 | AS36: 1.7679426 | AX36: 0.77354092 | AY36: 1.934143 | AZ36: 1.2654139 | BA36: 0.87727354 | BB36: 0.93777848
A37: 35 | B37: A_Brazl | C37: 01.d | D37: 01.25 | E37: Brazil nuts, with shell | F37: tonnes | K37: 0.24929691 | BB37: 1.7652138
A38: 36 | B38: A_Broay | C38: 01.d | D38: 01.25 | E38: Broad beans, horse beans, dry | F38: tonnes | G38: 1.3684187 | H38: 2.555036 | I38: 0.85819434 | J38: 1.7450466 | K38: 17.449567 | M38: 1.4460928 | N38: 2.2332532 | O38: 1.3617646 | P38: 2.3829769 | Q38: 0.82179475 | T38: 2.5570139 | V38: 2.6640964 | W38: 0.7518969 | X38: 1.23838 | AA38: 1.3060092 | AC38: 0.12460846 | AE38: 2.1978175 | AF38: 3.8932369 | AI38: 2.4647179 | AK38: 0.92999734 | AL38: 1.9930799 | AM38: 1.2577049 | AO38: 1.875876 | AP38: 0.65522755 | AR38: 1.79489 | AS38: 0.84284627 | AT38: 1.1537723 | AU38: 2.5806124 | AV38: 0.94547804 | AY38: 0.54988678 | AZ38: 1.3641048 | BA38: 0.44951768 | BB38: 1.7858033 | BC38: 0.82083633
A39: 37 | B39: A_Cabbs | C39: 01.d | D39: 01.13 | E39: Cabbages and other brassicas | F39: tonnes | G39: 0.12170342 | H39: 0.39401449 | I39: 0.2892412 | J39: 0.24007122 | L39: 0.27915216 | M39: 0.39525684 | N39: 0.32980723 | O39: 0.18594289 | P39: 0.20940701 | Q39: 0.12849469 | R39: 0.16299727 | S39: 0.16324528 | T39: 0.13538757 | U39: 0.22263202 | V39: 0.26870801 | W39: 0.25106063 | X39: 0.15699634 | Z39: 0.23595323 | AA39: 0.20305945 | AB39: 0.30409136 | AC39: 0.24401994 | AD39: 0.14508583 | AE39: 0.36178881 | AF39: 0.55273365 | AG39: 0.28670681 | AH39: 0.16733797 | AI39: 0.5191407 | AJ39: 0.18703348 | AK39: 0.22856737 | AL39: 0.28636224 | AM39: 0.29434446 | AN39: 0.69436713 | AO39: 0.14412946 | AP39: 0.31544658 | AQ39: 0.17330232 | AR39: 0.17990621 | AS39: 0.20724159 | AT39: 0.23386953 | AU39: 0.11769874 | AV39: 0.21472488 | AW39: 0.01188246 | AX39: 0.25367081 | AY39: 0.16948581 | AZ39: 0.18549107 | BA39: 0.13177006 | BB39: 0.75271314 | BC39: 0.18200372 | BD39: 0.17264258
A40: 38 | B40: A_Carrs | C40: 01.d | D40: 01.13 | E40: Carrots and turnips | F40: tonnes | G40: 0.12707717 | H40: 0.38232305 | I40: 0.17668745 | J40: 0.16476763 | L40: 0.26238233 | M40: 0.37700048 | N40: 0.21728181 | O40: 0.24056147 | P40: 0.24831581 | Q40: 0.13072543 | R40: 0.18417554 | S40: 0.17895294 | T40: 0.093525496 | U40: 0.26210329 | V40: 0.1816563 | W40: 0.15762645 | X40: 0.15473326 | Z40: 0.2683751 | AA40: 0.13437836 | AB40: 0.37885693 | AC40: 0.16919302 | AD40: 0.21739613 | AE40: 0.23294146 | AF40: 0.60642149 | AG40: 0.41714927 | AH40: 0.21148543 | AI40: 0.77192224 | AJ40: 0.22685608 | AK40: 0.16929677 | AL40: 0.31675174 | AM40: 0.26207269 | AN40: 0.66801104 | AO40: 0.15906778 | AP40: 0.25318192 | AQ40: 0.263091 | AR40: 0.19505939 | AS40: 0.16131609 | AT40: 0.33820589 | AU40: 0.14973086 | AV40: 0.087804958 | AW40: 0.011588648 | AX40: 0.29960779 | AY40: 0.098470535 | AZ40: 0.20329464 | BA40: 0.10230076 | BB40: 0.39411094 | BC40: 0.17164671 | BD40: 0.32277431
...

Sheet GHG markets - hybrid
A1: GHG intensities: tonne CO2-eq. per unit | F1: MEUR/t | G1: ='GHG markets - hybrid'!G525/'GHG markets - monetary'!G452 * 1000 -> 2.2188454 | H1: ='GHG markets - hybrid'!H525/'GHG markets - monetary'!H452 * 1000 -> 12.543023 | I1: ='GHG markets - hybrid'!I525/'GHG markets - monetary'!I452 * 1000 -> 2.6645769 | J1: ='GHG markets - hybrid'!J525/'GHG markets - monetary'!J452 * 1000 -> 2.4186067 | K1: ='GHG markets - hybrid'!K525/'GHG markets - monetary'!K452 * 1000 -> 8.7587887 | L1: ='GHG markets - hybrid'!L525/'GHG markets - monetary'!L452 * 1000 -> 51.30281 | M1: ='GHG markets - hybrid'!M525/'GHG markets - monetary'!M452 * 1000 -> 2.1497588 | N1: ='GHG markets - hybrid'!N525/'GHG markets - monetary'!N452 * 1000 -> 5.2323261 | ... AJ1: ='GHG markets - hybrid'!AJ525/'GHG markets - monetary'!AJ452 * 1000 -> 2.5899762
A2: No | B2: EXIOBASE product code | C2: Nace rev1 code | D2: Nace rev2 code | E2: Description | F2: Unit | G2: AT | H2: AU | I2: BE | J2: BG | K2: BR | L2: CA | M2: CH | N2: CN | O2: CY | P2: CZ | Q2: DE | R2: DK | S2: EE | T2: ES | U2: FI | V2: FR | W2: GB | X2: GR | Y2: Global | Z2: HR | AA2: HU | AB2: ID | AC2: IE | AD2: IN | AE2: IT | AF2: JP | AG2: KR | AH2: LT | AI2: LU | AJ2: LV | AK2: MT | AL2: MX | AM2: NL | AN2: NO | AO2: PL | AP2: PT | AQ2: RO | AR2: RU | AS2: SE | AT2: SI | AU2: SK | AV2: TR | AW2: TW | AX2: US | AY2: WA | AZ2: WE | BA2: WF | BB2: WL | BC2: WM | BD2: ZA
A3: 1 | B3: M_Ricey | C3: 01.a | D3: 01.12 | E3: Rice, paddy, market of | F3: tonnes | G3: 2.7034813 | H3: 1.6837518 | I3: 2.7433509 | J3: 2.5012937 | K3: 1.831469 | L3: 2.246928 | M3: 2.5267356 | N3: 2.7750241 | O3: 1.5876481 | P3: 2.457337 | Q3: 2.8393737 | R3: 2.7468935 | S3: 2.4916298 | T3: 1.9568852 | U3: 1.9569039 | V3: 2.8888842 | W3: 2.2345233 | X3: 1.4821261 | Y3: 2.7123364 | Z3: 2.6571328 | AA3: 3.3831683 | AB3: 2.8331627 | AC3: 2.2550059 | AD3: 2.9258097 | AE3: 2.4191062 | AF3: 2.8048107 | AG3: 2.4831095 | AH3: 2.3390306 | AI3: 2.7644713 | AJ3: 1.9452962 | AK3: 2.2906356 | AL3: 2.0810677 | AM3: 2.5517708 | AN3: 2.4563285 | AO3: 2.6625415 | AP3: 2.2908518 | AQ3: 3.0960778 | AR3: 2.9872421 | AS3: 2.4538424 | AT3: 2.7099873 | AU3: 2.5481915 | AV3: 2.1105107 | AW3: 0.25797537 | AX3: 2.1455885 | AY3: 2.5472776 | AZ3: 3.1335171 | BA3: 2.8470643 | BB3: 2.6715977 | BC3: 2.3550325 | BD3: 4.8806297
A4: 2 | B4: M_Germt | C4: 01.b | D4: 01.11 | E4: Germ, wheat, market of | F4: tonnes | G4: 0.30966108 | H4: 0.59636788 | I4: 0.6289413 | J4: 5.5532462 | L4: 0.63285132 | M4: 0.10330556 | N4: 0.47788859 | O4: 1.859407 | P4: 0.42436654 | Q4: 0.09995143 | R4: 0.47878909 | S4: 0.36840919 | T4: 1.8072579 | U4: 0.30898634 | V4: 0.6333932 | W4: 1.8387945 | X4: 0.072804992 | Y4: 0.61738239 | Z4: 0.31848263 | AA4: 0.43242269 | AB4: 0.065197648 | AC4: 1.6829984 | AD4: 0.21673567 | AE4: 0.7794657 | AF4: 0.091454024 | AG4: 0.80375356 | AH4: 0.25522888 | AI4: 0.71351851 | AJ4: 0.36956472 | AK4: 1.2905606 | AL4: 0.46017257 | AM4: 1.4131758 | AN4: 0.42020436 | AO4: 1.153073 | AP4: 0.75322876 | AQ4: 0.21205587 | AR4: 1.8216443 | AS4: 0.50950623 | AT4: 0.53026317 | AU4: 0.39017964 | AV4: 0.39420195 | AW4: 0.080091711 | AX4: 0.36200909 | AY4: 0.23604252 | AZ4: 1.7216699 | BA4: 0.17932303 | BB4: 12.096097 | BC4: 0.54996805 | BD4: 0.80275922
A5: 3 | B5: M_Wheat | C5: 01.b | D5: 01.11 | E5: Wheat, market of | F5: tonnes | G5: 1.0090985 | H5: 1.5706298 | I5: 1.0977597 | J5: 1.081597 | K5: 1.8297677 | L5: 1.3304042 | M5: 1.2751885 | N5: 1.6597586 | O5: 1.4971719 | P5: 1.0839728 | Q5: 0.93792557 | R5: 0.90619688 | S5: 1.8790591 | T5: 1.1126208 | U5: 1.4681997 | V5: 1.2085173 | W5: 1.0733201 | X5: 1.135965 | Y5: 1.3869469 | Z5: 1.0565227 | AA5: 0.90867801 | AB5: 1.4587189 | AC5: 0.88121002 | AD5: 1.1815905 | AE5: 1.3364016 | AF5: 1.5325273 | AG5: 1.4477703 | AH5: 1.2056893 | AI5: 1.1262165 | AJ5: 1.5063884 | AK5: 1.145114 | AL5: 1.3369124 | AM5: 1.0902027 | AN5: 1.1936614 | AO5: 1.2225263 | AP5: 1.2155136 | AQ5: 1.0314689 | AR5: 1.5641129 | AS5: 1.1047241 | AT5: 1.1172161 | AU5: 0.97081145 | AV5: 1.3468692 | AW5: 1.5047137 | AX5: 1.4888908 | AY5: 1.6170861 | AZ5: 1.3844072 | BA5: 1.2139353 | BB5: 1.4215361 | BC5: 1.093147 | BD5: 1.2991782
A6: 4 | B6: M_Barly | C6: 01.c | D6: 01.11 | E6: Barley, market of | F6: tonnes | G6: 0.93162088 | H6: 1.412717 | I6: 1.0677338 | J6: 0.88266343 | K6: 1.0561585 | L6: 1.2191225 | M6: 1.1465735 | N6: 1.4997596 | O6: 1.5352057 | P6: 1.1933189 | Q6: 0.90060988 | R6: 0.93531521 | S6: 2.0276287 | T6: 1.1120685 | U6: 1.677671 | V6: 1.116545 | W6: 0.93674243 | X6: 0.95154859 | Y6: 1.2083829 | Z6: 1.2233425 | AA6: 0.97372033 | AB6: 1.0334758 | AC6: 0.83489913 | AD6: 1.1174693 | AE6: 1.5161462 | AF6: 1.7753116 | AG6: 3.4684164 | AH6: 1.510159 | AI6: 1.4888779 | AJ6: 2.1303779 | AK6: 1.1256397 | AL6: 2.1119661 | AM6: 1.0216333 | AN6: 1.3854379 | AO6: 1.6048521 | AP6: 1.1921595 | AQ6: 0.96312901 | AR6: 1.5062257 | AS6: 1.1385772 | AT6: 1.3451558 | AU6: 1.0577497 | AV6: 1.2591523 | AW6: 1.3714958 | AX6: 1.1859739 | AY6: 1.012029 | AZ6: 1.3827087 | BA6: 0.99537542 | BB6: 0.96000216 | BC6: 1.1736334 | BD6: 1.0456374
A7: 5 | B7: M_Buckt | C7: 01.c | D7: 01.11 | E7: Buckwheat, market of | F7: tonnes | G7: 3.3925127 | H7: 4.8021031 | I7: 3.5222284 | J7: 3.4182139 | K7: 4.0673982 | L7: 5.0650099 | M7: 3.3898139 | N7: 7.3366376 | O7: 3.7817082 | P7: 2.7075468 | Q7: 3.5042977 | R7: 3.4645536 | S7: 4.615424 | T7: 3.6182433 | U7: 4.4473505 | V7: 2.092172 | W7: 4.9279979 | X7: 3.5952353 | Y7: 3.8011452 | Z7: 4.0004743 | AA7: 3.0514675 | AB7: 3.8175588 | AC7: 4.7899535 | AD7: 3.2242016 | AE7: 3.5804949 | AF7: 8.5520256 | AG7: 10.601666 | AH7: 3.5659631 | AI7: 3.4881239 | AJ7: 4.701712 | AK7: 3.3209376 | AM7: 4.3085486 | AN7: 5.5937298 | AO7: 3.4022655 | AP7: 3.616555 | AQ7: 3.425752 | AR7: 2.6718612 | AS7: 4.142521 | AT7: 4.8982198 | AU7: 3.4431495 | AV7: 3.5216827 | AW7: 6.3950172 | AX7: 3.9607746 | AY7: 3.2344677 | AZ7: 3.7020822 | BA7: 0.64009168 | BB7: 5.2975609 | BC7: 3.8524882 | BD7: 7.1198199
A8: 6 | B8: M_Ceres | C8: 01.c | D8: 01.11 | E8: Cereals nes, market of | F8: tonnes | G8: 0.78966493 | H8: 1.4094301 | I8: 0.89431123 | J8: 1.1702994 | K8: 1.1667804 | L8: 1.1155835 | M8: 1.0223166 | N8: 1.0391255 | O8: 1.0418404 | P8: 1.8211092 | Q8: 1.3760342 | R8: 1.039567 | S8: 1.6805684 | T8: 0.95871785 | U8: 1.8806728 | V8: 0.921512 | W8: 1.165501 | X8: 0.67864268 | Y8: 0.4083897 | Z8: 1.0126151 | AA8: 0.9081509 | AB8: 0.91556109 | AC8: 1.4502587 | AD8: 0.48097134 | AE8: 1.0036318 | AF8: 0.58967073 | AG8: 1.6866803 | AH8: 2.0289858 | AI8: 0.88656696 | AJ8: 1.7436428 | AK8: 0.4538758 | AL8: 1.7026245 | AM8: 0.97744257 | AN8: 1.0347606 | AO8: 1.5075831 | AP8: 1.0138966 | AQ8: 1.2910828 | AR8: 3.0909513 | AS8: 1.0323857 | AT8: 0.79315807 | AU8: 2.5852342 | AV8: 0.37698665 | AW8: 0.49315594 | AX8: 1.3267745 | AY8: 0.34006912 | AZ8: 1.1551191 | BA8: 0.34530736 | BB8: 1.8446436 | BC8: 0.7450977 | BD8: 2.7771296
A9: 7 | B9: M_Fonio | C9: 01.c | D9: 01.29 | E9: Fonio, market of | F9: tonnes | G9: 0.73777327 | I9: 0.73777327 | L9: 0.73777327 | M9: 0.73777327 | O9: 0.73777327 | P9: 0.73777327 | Q9: 0.73777327 | R9: 0.73777327 | T9: 0.73777327 | V9: 0.73777327 | W9: 0.73777327 | X9: 0.73777327 | Y9: 0.73777327 | AB9: 0.73777327 | AC9: 0.73777327 | AE9: 0.73777327 | AH9: 0.73777327 | AI9: 0.73777327 | AM9: 0.73777327 | AO9: 0.73777327 | AP9: 0.73777327 | AQ9: 0.73777327 | AS9: 0.73777327 | AX9: 0.73777327 | AZ9: 0.73777327 | BA9: 0.73777327 | BC9: 0.73777327
A10: 8 | B10: M_Germe | C10: 01.c | D10: 01.19 | E10: Germ, maize, market of | F10: tonnes | G10: 0.13465036 | H10: 0.27767839 | I10: 0.26951667 | J10: 0.092309205 | K10: 0.081855462 | L10: 0.24045252 | M10: 0.22498475 | N10: 0.26482772 | O10: 0.093742081 | P10: 0.13792103 | Q10: 0.026858557 | R10: 0.17083627 | S10: 0.14079879 | T10: 0.21455931 | U10: 0.17088832 | V10: 0.16905252 | W10: 0.095081175 | X10: 0.035974917 | Y10: 0.17242369 | Z10: 0.16503306 | AA10: 0.15264821 | AB10: 0.09788484 | AC10: 0.13889351 | AD10: 0.17381485 | AE10: 0.28045172 | AF10: 0.93019905 | AG10: 0.35997403 | AH10: 0.13992504 | AI10: 0.23191287 | AJ10: 0.29492031 | AK10: 0.095861839 | AL10: 0.20733447 | AM10: 0.47861697 | AN10: 0.17088832 | AO10: 0.27836821 | AP10: 0.2675483 | AQ10: 0.091680723 | AR10: 0.22587892 | AS10: 0.0230167 | AT10: 0.23035176 | AU10: 0.089315501 | AV10: 0.18054089 | AW10: 0.003796862 | AX10: 0.12986424 | AY10: 0.16080747 | AZ10: 0.11593331 | BA10: 0.049085802 | BB10: 0.19677516 | BC10: 0.37182629 | BD10: 0.38418783
A11: 9 | B11: M_Graid | C11: 01.c | D11: 01.11 | E11: Grain, mixed, market of | F11: tonnes | G11: 1.4282035 | I11: 2.2782375 | J11: 1.4057604 | L11: 1.5959109 | M11: 1.3980298 | N11: 1.7693228 | O11: 2.1141597 | P11: 1.9767199 | Q11: 1.565319 | R11: 1.3194943 | S11: 2.3817762 | T11: 2.0293504 | U11: 2.2803178 | V11: 1.8392274 | W11: 0.98449982 | X11: 1.127864 | Y11: 2.0168376 | Z11: 2.0511401 | AA11: 1.8973645 | AC11: 2.2441459 | AD11: 2.2833932 | AE11: 1.7510112 | AH11: 2.1900829 | AI11: 1.6676463 | AJ11: 4.5668597 | AK11: 1.2570056 | AM11: 2.2499968 | AN11: 1.545814 | AO11: 2.0808125 | AP11: 1.545814 | AQ11: 1.5666099 | AS11: 1.6982002 | AT11: 1.6600088 | AU11: 1.4398319 | AV11: 1.879883 | AX11: 1.8408457 | AY11: 0.60649867 | AZ11: 1.7537465 | BA11: 2.2833932 | BB11: 1.545814 | BC11: 2.2723968
A12: 10 | B12: M_Hops | C12: 01.c | D12: 01.28 | E12: Hops, market of | F12: tonnes | G12: 2.3778772 | H12: 3.1415977 | I12: 2.7538317 | J12: 2.7111933 | K12: 2.5849159 | L12: 2.8746344 | M12: 2.2888509 | N12: 4.0340287 | O12: 3.8403813 | P12: 4.4534038 | Q12: 2.4828312 | R12: 2.2866271 | S12: 2.3043355 | T12: 2.4171332 | U12: 2.7032489 | V12: 2.846412 | W12: 2.7412485 | X12: 2.3145808 | Y12: 2.5858921 | Z12: 2.569335 | AA12: 2.7114676 | AB12: 2.532335 | AC12: 2.5153235 | AD12: 2.6205317 | AE12: 3.0486119 | AF12: 3.1803241 | AG12: 2.7174348 | AH12: 2.3360437 | AI12: 2.3448922 | AJ12: 2.7731861 | AK12: 1.5614844 | AL12: 2.8916692 | AM12: 2.3584933 | AN12: 2.244591 | AO12: 2.8010976 | AP12: 2.2262177 | AQ12: 2.605093 | AR12: 2.8461033 | AS12: 2.2119535 | AT12: 2.8082453 | AU12: 2.6159174 | AV12: 2.3765646 | AW12: 2.524705 | AX12: 2.9157823 | AY12: 4.6038373 | AZ12: 5.7298512 | BA12: 1.0589902 | BB12: 2.7236373 | BC12: 1.2962169 | BD12: 3.8936973
A13: 11 | B13: M_Maize | C13: 01.c | D13: 01.11 | E13: Maize, market of | F13: tonnes | G13: 0.47836777 | H13: 0.39926279 | I13: 0.6795399 | J13: 1.0368718 | K13: 1.2740478 | L13: 0.56375598 | M13: 0.71179696 | N13: 1.0600853 | O13: 0.78011853 | P13: 0.68504897 | Q13: 0.64861446 | R13: 0.66983623 | S13: 0.7028431 | T13: 0.57062849 | U13: 0.61425691 | V13: 0.73374648 | W13: 0.71752574 | X13: 0.41330712 | Y13: 0.79053392 | Z13: 0.60695307 | AA13: 0.49295106 | AB13: 1.1597808 | AC13: 0.68719638 | AD13: 1.1434724 | AE13: 0.61501786 | AF13: 0.68827463 | AG13: 0.73418858 | AH13: 0.70717853 | AI13: 0.67026538 | AJ13: 0.70005812 | AK13: 0.71073953 | AL13: 1.0528988 | AM13: 0.77482498 | AN13: 0.70841139 | AO13: 0.72229077 | AP13: 0.71156358 | AQ13: 0.74571989 | AR13: 0.70069883 | AS13: 0.69623797 | AT13: 0.61486245 | AU13: 0.54782285 | AV13: 0.56025071 | AW13: 0.77413924 | AX13: 0.54815402 | AY13: 0.73822987 | AZ13: 0.75245368 | BA13: 0.66183119 | BB13: 0.69629188 | BC13: 0.77794981 | BD13: 0.88624064
A14: 12 | B14: M_Maizn | C14: 01.c | D14: 01.11 | E14: Maize, green, market of | F14: tonnes | G14: 0.51346798 | H14: 0.56144661 | I14: 0.52795372 | J14: 0.72775693 | K14: 0.51493593 | L14: 0.69802658 | M14: 0.87866828 | N14: 1.8574577 | O14: 0.32875148 | P14: 0.53084204 | Q14: 0.56849257 | R14: 0.51332381 | S14: 0.58126795 | T14: 0.51356842 | U14: 0.51500138 | V14: 0.54116874 | W14: 0.54147896 | X14: 0.20779804 | Y14: 0.60994546 | Z14: 0.43187896 | AA14: 0.47908757 | AB14: 1.1984902 | AC14: 0.53554678 | AD14: 0.53809587 | AE14: 0.85843915 | AF14: 1.9191448 | AG14: 0.52085114 | AH14: 0.59324527 | AI14: 0.53794055 | AJ14: 0.61601625 | AK14: 0.51464265 | AL14: 0.64009699 | AM14: 0.52206303 | AN14: 0.85748213 | AO14: 0.68441513 | AP14: 0.51493601 | AQ14: 0.95337837 | AR14: 0.59324525 | AS14: 0.50708316 | AT14: 0.61170271 | AU14: 0.54535846 | AV14: 0.522063 | AW14: 0.50771659 | AX14: 0.50727818 | AY14: 1.0026829 | AZ14: 0.49664681 | BA14: 0.45367638 | BB14: 0.54950589 | BC14: 0.71685451 | BD14: 0.8884091
A15: 13 | B15: M_Millt | C15: 01.c | D15: 01.11 | E15: Millet, market of | F15: tonnes | G15: 1.1414987 | H15: 1.9793902 | I15: 1.9744365 | J15: 2.0363509 | K15: 1.6140313 | L15: 1.1232608 | M15: 1.6611755 | N15: 2.1748669 | O15: 2.0741818 | P15: 3.1444493 | Q15: 1.8294218 | R15: 1.8734002 | S15: 2.5617806 | T15: 1.8831123 | U15: 1.4732408 | V15: 1.6880466 | W15: 1.9859134 | X15: 1.766918 | Y15: 1.450526 | Z15: 2.9154691 | AA15: 1.9963025 | AB15: 1.1715373 | AC15: 1.9926848 | AD15: 2.0034801 | AE15: 2.0266886 | AF15: 1.9621371 | AG15: 3.4347576 | AH15: 2.2591745 | AI15: 1.6659131 | AJ15: 2.3430963 | AK15: 2.0664973 | AL15: 1.0859683 | AM15: 2.0095011 | AN15: 1.9574941 | AO15: 2.2700292 | AP15: 2.0244936 | AQ15: 1.8206821 | AR15: 1.6482235 | AS15: 2.045107 | AT15: 2.8100966 | AU15: 2.1340652 | AV15: 1.6189921 | AW15: 1.3443419 | AX15: 1.0702944 | AY15: 1.569451 | AZ15: 2.1254214 | BA15: 0.92186394 | BB15: 1.4775995 | BC15: 2.0917776 | BD15: 3.1087632
A16: 14 | B16: M_Mushs | C16: 01.c | D16: 01.13 | E16: Mushrooms and truffles, market of | F16: tonnes | G16: 0.30509237 | H16: 0.6891235 | I16: 0.459033 | J16: 0.39944846 | K16: 0.87612155 | L16: 0.57320062 | M16: 0.58806955 | N16: 0.67387764 | O16: 0.82863237 | P16: 0.43990574 | Q16: 0.36386762 | R16: 0.47673506 | S16: 0.35730017 | T16: 0.34188851 | U16: 1.1936521 | V16: 0.32743476 | W16: 0.28901356 | X16: 0.42242136 | Y16: 0.64201246 | Z16: 0.50896016 | AA16: 0.22606646 | AB16: 0.17033251 | AC16: 0.27401099 | AD16: 0.36385101 | AE16: 1.0173754 | AF16: 1.0003877 | AG16: 0.52601268 | AH16: 0.88928277 | AI16: 0.4297288 | AJ16: 0.34895214 | AK16: 1.834623 | AL16: 0.22333028 | AM16: 0.6554204 | AN16: 0.48783739 | AO16: 0.41365471 | AP16: 0.64518508 | AQ16: 0.23376861 | AR16: 1.0778263 | AS16: 0.35570929 | AT16: 0.44460537 | AU16: 0.39672629 | AV16: 0.33511107 | AW16: 0.099342153 | AX16: 0.23256465 | AY16: 0.59224128 | AZ16: 0.37618161 | BA16: 0.66156054 | BB16: 0.23692191 | BC16: 1.5383097 | BD16: 0.64650686
A17: 15 | B17: M_Oatss | C17: 01.c | D17: 01.11 | E17: Oats, market of | F17: tonnes | G17: 0.98817734 | H17: 1.5943332 | I17: 1.1375675 | J17: 1.6919072 | K17: 1.7464084 | L17: 1.1177485 | M17: 1.3130222 | N17: 1.6649912 | O17: 5.1306355 | P17: 1.5600694 | Q17: 1.1904849 | R17: 0.88630326 | S17: 2.0651088 | T17: 1.4219016 | U17: 1.4380895 | V17: 1.0511663 | W17: 0.82158375 | X17: 1.109215 | Y17: 1.4148121 | Z17: 1.4462322 | AA17: 1.2925257 | AB17: 1.5713105 | AC17: 0.59446798 | AD17: 1.8317815 | AE17: 2.0551064 | AF17: 1.2057595 | AG17: 1.1870283 | AH17: 1.9102388 | AI17: 1.0765415 | AJ17: 2.446419 | AK17: 1.1398328 | AL17: 1.6922799 | AM17: 1.3888017 | AN17: 1.0688919 | AO17: 1.8371787 | AP17: 2.5503629 | AQ17: 1.3230734 | AR17: 1.584189 | AS17: 1.0964297 | AT17: 1.4697155 | AU17: 1.6351602 | AV17: 1.1400215 | AW17: 1.4486499 | AX17: 1.2497412 | AY17: 1.0388581 | AZ17: 1.8606413 | BA17: 0.73996298 | BB17: 1.1576281 | BC17: 1.2772793 | BD17: 1.6098571
A18: 16 | B18: M_Poppd | C18: 01.c | D18: 01.11 | E18: Poppy seed, market of | F18: tonnes | G18: 4.913068 | H18: 3.9276782 | I18: 5.6322307 | J18: 4.0729265 | K18: 4.7873109 | L18: 3.9240043 | M18: 5.6424059 | N18: 7.0597624 | O18: 5.003049 | P18: 4.9909281 | Q18: 5.3955 | R18: 4.5923271 | S18: 4.4418605 | T18: 2.5552028 | U18: 4.1441825 | V18: 4.3883557 | W18: 3.6775512 | X18: 4.8497794 | Y18: 4.261175 | Z18: 3.9637731 | AA18: 3.825085 | AB18: 4.7474493 | AC18: 4.0871429 | AD18: 3.9398911 | AE18: 4.7873109 | AF18: 3.9287535 | AG18: 4.8759873 | AH18: 5.0759776 | AI18: 5.6419832 | AJ18: 6.7133992 | AK18: 4.5242841 | AL18: 3.5613674 | AM18: 4.3353327 | AN18: 4.9534211 | AO18: 4.5461964 | AP18: 3.5908735 | AQ18: 5.1632379 | AR18: 5.1523598 | AS18: 4.2293669 | AT18: 4.2567929 | AU18: 4.131106 | AV18: 3.8430714 | AX18: 3.5613674 | AY18: 4.7474485 | AZ18: 4.5774838 | BA18: 4.2174325 | BB18: 3.8067412 | BC18: 1.8000595 | BD18: 4.4323023
A19: 17 | B19: M_Quina | C19: 01.c | D19: 01.11 | E19: Quinoa, market of | F19: tonnes | G19: 3.5709594 | H19: 3.5709593 | I19: 3.5709595 | J19: 3.5709591 | K19: 3.5709595 | L19: 3.5709588 | M19: 3.5709591 | N19: 3.5709595 | O19: 3.5709594 | P19: 3.5709592 | Q19: 3.5709593 | R19: 3.5709592 | S19: 3.5709593 | T19: 3.5709594 | U19: 3.5709592 | V19: 3.570958 | W19: 3.5709592 | X19: 3.570959 | Y19: 3.5709595 | Z19: 3.5709594 | AA19: 3.5709594 | AB19: 3.5709595 | AC19: 3.5709594 | AD19: 3.5709594 | AE19: 3.570959 | AF19: 3.5709594 | AG19: 3.5709595 | AH19: 3.5709592 | AI19: 3.5709593 | AJ19: 3.5709594 | AK19: 3.5709591 | AL19: 3.570959 | AM19: 3.5709593 | AN19: 3.5709593 | AO19: 3.5709595 | AP19: 3.570959 | AQ19: 3.5709593 | AR19: 3.5709595 | AS19: 3.5709593 | AT19: 3.570959 | AU19: 3.5709592 | AV19: 3.5709589 | AW19: 3.5709583 | AX19: 3.5709591 | AY19: 3.570959 | AZ19: 3.5709593 | BA19: 3.5709592 | BB19: 3.5709595 | BC19: 3.5709591 | BD19: 3.5709595
A20: 18 | B20: M_Ryee | C20: 01.c | D20: 01.11 | E20: Rye, market of | F20: tonnes | G20: 0.78647865 | H20: 3.7108711 | I20: 1.0548071 | J20: 1.5482607 | K20: 2.8270423 | L20: 0.90352227 | M20: 1.1833775 | N20: 1.1744676 | O20: 1.0258756 | P20: 1.1241136 | Q20: 0.92999072 | R20: 0.7038905 | S20: 1.6142195 | T20: 1.3380877 | U20: 1.4352947 | V20: 1.341685 | W20: 2.2069971 | X20: 1.0217775 | Y20: 1.2406428 | Z20: 1.2252932 | AA20: 1.155874 | AB20: 1.4114616 | AC20: 1.4437902 | AD20: 1.5674785 | AE20: 1.2587636 | AF20: 0.92782334 | AG20: 1.7075854 | AH20: 1.7164839 | AI20: 1.0738223 | AJ20: 1.425296 | AK20: 1.5935075 | AL20: 2.3686776 | AM20: 0.99063077 | AN20: 0.91367043 | AO20: 1.5118059 | AP20: 2.8392313 | AQ20: 1.1611794 | AR20: 1.2232989 | AS20: 0.78999466 | AT20: 1.228851 | AU20: 1.1512758 | AV20: 0.95708461 | AW20: 2.5038879 | AX20: 1.4792078 | AY20: 1.4127008 | AZ20: 2.0376386 | BA20: 0.88879113 | BB20: 2.0018498 | BC20: 0.96137736 | BD20: 2.0502406
A21: 19 | B21: M_Sorgm | C21: 01.c | D21: 01.11 | E21: Sorghum, market of | F21: tonnes | G21: 0.6402326 | H21: 0.97455934 | I21: 0.9008373 | J21: 1.3073598 | K21: 2.4544987 | L21: 1.0593949 | M21: 0.90984942 | N21: 1.0631778 | O21: 0.86040494 | P21: 1.9775674 | Q21: 0.92842978 | R21: 0.92732816 | S21: 0.90979951 | T21: 0.87726171 | U21: 0.90064924 | V21: 0.83541054 | W21: 0.90025202 | X21: 1.0061875 | Y21: 1.0985483 | Z21: 2.4085152 | AA21: 0.93795833 | AB21: 1.0207485 | AC21: 0.89677651 | AD21: 3.2555407 | AE21: 0.9573439 | AF21: 1.0916862 | AG21: 2.719454 | AH21: 1.0085887 | AI21: 0.83432121 | AJ21: 0.92842976 | AK21: 0.99016224 | AL21: 1.5219256 | AM21: 0.86040489 | AN21: 0.87057676 | AO21: 1.0174797 | AP21: 0.80780363 | AQ21: 0.91460965 | AR21: 1.6438662 | AS21: 0.87366937 | AT21: 0.92148795 | AU21: 1.466319 | AV21: 1.4344083 | AW21: 1.1480234 | AX21: 1.0102438 | AY21: 1.3956837 | AZ21: 0.99921492 | BA21: 0.68760012 | BB21: 1.1017495 | BC21: 1.051489 | BD21: 1.4373765
A22: 20 | B22: M_Trite | C22: 01.c | D22: 01.11 | E22: Triticale, market of | F22: tonnes | G22: 0.98813978 | H22: 1.7983672 | I22: 1.1162869 | J22: 1.0787378 | K22: 1.9437693 | L22: 1.2799216 | M22: 1.3065092 | N22: 2.502787 | O22: 1.0205241 | P22: 1.3162913 | Q22: 0.94629115 | R22: 1.0080649 | S22: 1.5510404 | T22: 1.4214067 | U22: 1.3028637 | V22: 1.0501935 | W22: 1.1474744 | X22: 0.9631696 | Y22: 1.3406064 | Z22: 1.1921159 | AA22: 1.043582 | AC22: 0.94581569 | AE22: 1.2467767 | AF22: 1.7983672 | AH22: 1.3214938 | AI22: 1.3934267 | AJ22: 1.7615902 | AK22: 1.4346749 | AL22: 1.6392117 | AM22: 0.93381742 | AN22: 1.0520392 | AO22: 1.4787536 | AP22: 2.9235205 | AQ22: 0.88343761 | AR22: 1.0679283 | AS22: 1.0828296 | AT22: 1.2156469 | AU22: 1.1249953 | AV22: 0.95938513 | AX22: 1.2801858 | AY22: 0.99926422 | AZ22: 1.9226479 | BA22: 0.34614823 | BB22: 0.69624056 | BC22: 1.3433097 | BD22: 0.34601534
A23: 21 | B23: M_Almol | C23: 01.d | D23: 01.25 | E23: Almonds, with shell, market of | F23: tonnes | G23: 3.9137826 | H23: 1.4015008 | I23: 1.565375 | J23: 4.4563203 | K23: 6.1297319 | L23: 1.2987992 | M23: 3.1473902 | N23: 2.3536278 | O23: 21.994154 | P23: 4.0849942 | Q23: 2.5600099 | R23: 3.2604681 | S23: 1.2914765 | T23: 7.1281853 | U23: 1.3210637 | V23: 4.9024923 | W23: 1.4710402 | X23: 1.0182119 | Y23: 2.0656556 | Z23: 6.3839906 | AA23: 5.7751785 | AB23: 1.2968469 | AC23: 1.8350737 | AD23: 1.3521761 | AE23: 3.1046039 | AF23: 1.2781114 | AG23: 1.2811916 | AH23: 2.7732803 | AI23: 3.255966 | AJ23: 2.5734228 | AK23: 2.668376 | AL23: 1.4325829 | AM23: 2.3533496 | AN23: 1.8423804 | AO23: 5.5279987 | AP23: 10.863052 | AQ23: 3.546738 | AR23: 2.1505264 | AS23: 3.1759185 | AT23: 3.5080326 | AU23: 2.673688 | AV23: 1.4340022 | AW23: 1.4576162 | AX23: 1.2766609 | AY23: 1.9197916 | AZ23: 1.313741 | BA23: 3.251459 | BB23: 2.0150446 | BC23: 1.6843534 | BD23: 1.7328149
A24: 22 | B24: M_Anisr | C24: 01.d | D24: 01.28 | E24: Anise, badian, fennel, coriander, market of | F24: tonnes | G24: 3.7871404 | H24: 4.6507947 | I24: 3.767965 | J24: 4.931778 | K24: 3.4517969 | L24: 4.7385496 | M24: 4.0211073 | N24: 6.7565675 | O24: 3.0932919 | P24: 3.7433517 | Q24: 3.9528739 | R24: 4.7373743 | S24: 3.8463307 | T24: 3.5017834 | U24: 4.077589 | V24: 3.858103 | W24: 3.5249829 | X24: 2.803352 | Y24: 3.378526 | Z24: 3.4354883 | AA24: 2.6926225 | AB24: 4.4714499 | AC24: 3.6035516 | AD24: 3.3230769 | AE24: 3.6938323 | AF24: 2.4702939 | AG24: 3.9598435 | AH24: 3.7020934 | AI24: 3.8887379 | AJ24: 3.7304874 | AK24: 3.7255264 | AL24: 0.80154073 | AM24: 3.9274877 | AN24: 3.8609806 | AO24: 4.1099744 | AP24: 3.7039196 | AQ24: 2.1681402 | AR24: 4.6474412 | AS24: 3.8150608 | AT24: 3.9669214 | AU24: 3.5991893 | AV24: 5.9121158 | AW24: 5.7831716 | AX24: 3.7504038 | AY24: 3.783648 | AZ24: 4.4046142 | BA24: 1.7090504 | BB24: 3.5742312 | BC24: 2.4872303 | BD24: 3.3937682
A25: 23 | B25: M_Appls | C25: 01.d | D25: 01.22 | E25: Apples, market of | F25: tonnes | G25: 0.26076093 | H25: 0.73233846 | I25: 0.37775826 | J25: 0.44384388 | K25: 0.31976275 | L25: 0.40499048 | M25: 0.34815868 | N25: 0.64055883 | O25: 0.57796205 | P25: 0.44130171 | Q25: 0.30171525 | R25: 0.37519531 | S25: 0.82315956 | T25: 0.3441387 | U25: 0.46745862 | V25: 0.33045928 | W25: 0.41734818 | X25: 0.20714687 | Y25: 0.54905748 | Z25: 0.63607656 | AA25: 0.35092055 | AB25: 0.55266936 | AC25: 0.40550764 | AD25: 0.3776642 | AE25: 0.43888877 | AF25: 1.2667482 | AG25: 0.75017059 | AH25: 0.61776478 | AI25: 0.60824375 | AJ25: 0.60311531 | AK25: 0.46050263 | AL25: 0.60007989 | AM25: 0.60272015 | AN25: 0.61276041 | AO25: 0.41645419 | AP25: 0.55349264 | AQ25: 0.42517949 | AR25: 0.50136526 | AS25: 0.42911864 | AT25: 0.41968685 | AU25: 0.42198256 | AV25: 0.40631253 | AW25: 0.65571656 | AX25: 0.35199037 | AY25: 0.57288681 | AZ25: 0.45665058 | BA25: 0.4725434 | BB25: 0.71021652 | BC25: 0.42600979 | BD25: 1.0345022
A26: 24 | B26: M_Apris | C26: 01.d | D26: 01.24 | E26: Apricots, market of | F26: tonnes | G26: 0.74810013 | H26: 2.3463007 | I26: 0.44025218 | J26: 0.68058493 | K26: 0.94290948 | L26: 0.63369049 | M26: 0.52275465 | N26: 3.2632935 | O26: 1.3636321 | P26: 1.2470827 | Q26: 0.53954564 | R26: 0.65639508 | S26: 0.49734984 | T26: 0.57108818 | U26: 0.62213915 | V26: 0.31522048 | W26: 0.62952025 | X26: 0.27730848 | Y26: 0.68670765 | Z26: 0.96283343 | AA26: 0.78342746 | AB26: 1.998271 | AC26: 0.60048985 | AD26: 1.1603532 | AE26: 0.66363277 | AF26: 2.2569039 | AG26: 0.60894446 | AH26: 0.56022033 | AI26: 0.38796376 | AJ26: 0.51406991 | AK26: 0.65850901 | AL26: 0.78419968 | AM26: 0.62390352 | AN26: 0.59994754 | AO26: 0.97774274 | AP26: 0.81703129 | AQ26: 0.34451481 | AR26: 0.65532807 | AS26: 0.58301653 | AT26: 0.63419926 | AU26: 1.7072815 | AV26: 0.79097052 | AW26: 0.015795712 | AX26: 0.61416336 | AY26: 0.72642871 | AZ26: 0.60184034 | BA26: 0.42888266 | BB26: 0.96903267 | BC26: 0.61535741 | BD26: 1.3570952
A27: 25 | B27: M_Arecs | C27: 01.d | D27: 01.25 | E27: Areca nuts, market of | F27: tonnes | G27: 2.1394317 | H27: 2.4143064 | I27: 1.8402256 | L27: 1.8134542 | M27: 1.7562436 | N27: 4.6401391 | O27: 0 | Q27: 2.1394317 | R27: 2.2183782 | T27: 2.7791443 | U27: 2.8480103 | V27: 8.7649931 | W27: 2.8698688 | X27: 2.8480103 | Y27: 2.4236421 | AA27: 2.8382738 | AB27: 10.011604 | AC27: 2.8477796 | AD27: 1.9451236 | AE27: 2.7181042 | AF27: 4.5273883 | AG27: 10.027341 | AJ27: 2.2183782 | AM27: 2.2183782 | AP27: 2.5473789 | AQ27: 2.2183782 | AS27: 2.8480103 | AV27: 2.2183782 | AW27: 0.017141534 | AX27: 3.2682153 | AY27: 5.0871412 | AZ27: 3.0894314 | BA27: 2.2424452 | BB27: 8.5834342 | BC27: 2.2982125 | BD27: 3.6720215
A28: 26 | B28: M_Artis | C28: 01.d | D28: 01.13 | E28: Artichokes, market of | F28: tonnes | G28: 0.74178628 | I28: 0.92822319 | J28: 0.71620476 | L28: 0.47460988 | M28: 0.88488044 | N28: 2.557272 | O28: 0.43967435 | P28: 0.66303295 | Q28: 0.73408666 | R28: 0.78410484 | S28: 0.52413876 | T28: 0.30113525 | U28: 0.86714515 | V28: 0.89881526 | W28: 0.82754995 | X28: 0.37789165 | Y28: 0.61724432 | Z28: 0.7121457 | AA28: 0.77102237 | AB28: 0.5032328 | AC28: 0.86041063 | AE28: 0.71495121 | AF28: 0.61153967 | AG28: 0.92822321 | AH28: 0.52093824 | AI28: 0.92796163 | AJ28: 0.78054179 | AK28: 0.35543405 | AL28: 0.65549415 | AM28: 0.84249262 | AN28: 0.84329238 | AO28: 0.87905944 | AP28: 0.51653669 | AQ28: 0.32037911 | AR28: 0.30296923 | AS28: 0.87750165 | AT28: 0.68121561 | AU28: 0.64502671 | AV28: 0.60377992 | AW28: 0.63321025 | AX28: 0.47465024 | AY28: 0.37372347 | AZ28: 0.5644214 | BA28: 0.14237781 | BB28: 0.78172195 | BC28: 0.26692678 | BD28: 0.14236938
A29: 27 | B29: M_Aspas | C29: 01.d | D29: 01.13 | E29: Asparagus, market of | F29: tonnes | G29: 1.4089679 | H29: 1.1918202 | I29: 1.0891574 | J29: 0.99505241 | K29: 0.85402695 | L29: 1.3517467 | M29: 1.4659514 | N29: 1.907229 | O29: 1.2730665 | P29: 1.8648314 | Q29: 1.271634 | R29: 1.3088134 | S29: 1.5557705 | T29: 0.77675835 | U29: 1.2320356 | V29: 1.2447451 | W29: 1.5104879 | X29: 0.67478852 | Y29: 1.7967633 | Z29: 0.93995017 | AA29: 1.0073251 | AB29: 0.99467326 | AC29: 1.5990176 | AD29: 0.74453215 | AE29: 0.95020644 | AF29: 1.9255864 | AG29: 1.0636689 | AH29: 0.83046298 | AI29: 1.1028938 | AJ29: 1.1417346 | AK29: 1.3017004 | AL29: 0.80973719 | AM29: 1.3618179 | AN29: 1.4022609 | AO29: 0.85468296 | AP29: 0.75278129 | AQ29: 1.2854855 | AR29: 0.80217842 | AS29: 1.2683709 | AT29: 1.3984874 | AU29: 1.1568639 | AV29: 1.5113224 | AW29: 0.40322777 | AX29: 0.92796287 | AY29: 0.66701837 | AZ29: 1.2578985 | BA29: 0.38698619 | BB29: 0.84944342 | BC29: 0.61253669 | BD29: 0.80916842
A30: 28 | B30: M_Avocs | C30: 01.d | D30: 01.22 | E30: Avocados, market of | F30: tonnes | G30: 0.9662699 | H30: 1.2833774 | I30: 0.91303013 | J30: 0.79356145 | K30: 0.45818322 | L30: 1.1375719 | M30: 0.96981984 | N30: 1.8612024 | O30: 0.99707763 | P30: 0.9487008 | Q30: 0.96157521 | R30: 0.9668186 | S30: 0.91189553 | T30: 0.78463521 | U30: 0.88406301 | V30: 0.79396537 | W30: 0.97523225 | X30: 0.73848795 | Y30: 0.92333203 | Z30: 0.94448426 | AA30: 0.94206903 | AB30: 0.57535305 | AC30: 1.0003849 | AD30: 1.1140311 | AE30: 0.88266921 | AF30: 1.0269757 | AG30: 1.126908 | AH30: 0.92624347 | AI30: 0.85041266 | AJ30: 0.83379256 | AK30: 0.94132192 | AL30: 1.0205271 | AM30: 1.0287287 | AN30: 1.0150558 | AO30: 0.8929162 | AP30: 0.74410478 | AQ30: 0.86578053 | AR30: 0.81026909 | AS30: 0.96922913 | AT30: 0.78766241 | AU30: 0.95631617 | AV30: 1.1357111 | AW30: 1.1778291 | AX30: 1.0600353 | AY30: 0.8784934 | AZ30: 1.0788409 | BA30: 0.41881523 | BB30: 0.97193377 | BC30: 0.67421928 | BD30: 1.5938457
A31: 29 | B31: M_Bambs | C31: 01.d | D31: 01.25 | E31: Bambara beans, market of | F31: tonnes | G31: 0.000412552 | I31: 0.000650395 | J31: 0.000535924 | L31: 0.00546233 | M31: 0.000651188 | N31: 1.0026368 | O31: 0.000306133 | P31: 6.27e-06 | Q31: 0.000675287 | R31: 0.000651188 | S31: 0.49010285 | T31: 0.84835078 | U31: 0.000651188 | V31: 0.001836074 | W31: 0.49027901 | X31: 0.000651188 | Y31: 1.0026368 | Z31: 0.000651188 | AA31: 0.000536882 | AB31: 0.000560084 | AE31: 3.26e-05 | AG31: 0.000368686 | AI31: 0.000368686 | AJ31: 0.000651188 | AK31: 0.000651188 | AM31: 0.000305396 | AN31: 0.000305396 | AO31: 0.000651188 | AP31: 0.000651188 | AQ31: 0.000415866 | AS31: 0.000646078 | AT31: 0.000309944 | AU31: 0.000343663 | AV31: 0.000368686 | AX31: 0.000612684 | AY31: 0.000869812 | BA31: 1.0002216 | BB31: 2.3e-05 | BC31: 0.003651127 | BD31: 0.000651188
A32: 30 | B32: M_Banas | C32: 01.d | D32: 01.22 | E32: Bananas, market of | F32: tonnes | G32: 0.41711765 | H32: 0.66417165 | I32: 0.41184975 | J32: 0.36318231 | K32: 0.49420343 | L32: 0.61452295 | M32: 0.42126912 | N32: 0.71755402 | O32: 0.62211174 | P32: 0.41171131 | Q32: 0.41937068 | R32: 0.4197433 | S32: 0.41842061 | T32: 0.31927718 | U32: 0.42159684 | V32: 0.38699461 | W32: 0.41634923 | X32: 0.42390511 | Y32: 0.37110193 | Z32: 0.43119067 | AA32: 0.41872928 | AB32: 0.17522797 | AC32: 0.42129928 | AD32: 0.2195334 | AE32: 0.41677605 | AF32: 0.36639099 | AG32: 0.36161468 | AH32: 0.41862753 | AI32: 0.41528633 | AJ32: 0.41701225 | AK32: 0.44731129 | AL32: 0.4714253 | AM32: 0.42184454 | AN32: 0.42219797 | AO32: 0.41874566 | AP32: 0.3610695 | AQ32: 0.40187046 | AR32: 0.42241471 | AS32: 0.421304 | AT32: 0.42826066 | AU32: 0.41396612 | AV32: 0.37038428 | AW32: 0.014923925 | AX32: 0.4253481 | AY32: 0.34356284 | AZ32: 0.41813996 | BA32: 0.35744659 | BB32: 0.42232654 | BC32: 0.40039197 | BD32: 0.99814932
A33: 31 | B33: M_Beann | C33: 01.d | D33: 01.25 | E33: Beans, green, market of | F33: tonnes | G33: 0.31913534 | H33: 0.97149686 | I33: 0.62308693 | J33: 0.40043668 | K33: 1.3125563 | L33: 0.76846097 | M33: 0.69620727 | N33: 0.27987309 | O33: 0.2396747 | P33: 1.2168402 | Q33: 0.46348265 | R33: 0.84765392 | S33: 0.88092536 | T33: 0.36643015 | U33: 1.199421 | V33: 0.57761429 | W33: 0.52870806 | X33: 0.35201216 | Y33: 0.32355688 | Z33: 1.0494906 | AA33: 0.3117783 | AB33: 0.59879309 | AC33: 0.7039605 | AD33: 0.88777556 | AE33: 0.56110473 | AF33: 0.35088232 | AG33: 1.2980355 | AH33: 0.9419824 | AI33: 0.81647269 | AJ33: 0.86569925 | AK33: 0.58897181 | AL33: 0.40956533 | AM33: 0.56529236 | AN33: 0.88329862 | AO33: 0.415178 | AP33: 0.36726155 | AQ33: 0.44687692 | AR33: 0.44133391 | AS33: 0.86301071 | AT33: 0.71393954 | AU33: 1.1402584 | AV33: 0.2422628 | AW33: 0.016408268 | AX33: 0.82653287 | AY33: 0.29847138 | AZ33: 1.6489049 | BA33: 0.14197542 | BB33: 0.97366995 | BC33: 0.30143399 | BD33: 1.0574546
A34: 32 | B34: M_Beany | C34: 01.d | D34: 01.25 | E34: Beans, dry, market of | F34: tonnes | G34: 1.4668593 | H34: 3.6361691 | I34: 2.0005173 | J34: 1.1642546 | K34: 3.2544586 | L34: 2.0772849 | M34: 2.1729129 | N34: 1.9548149 | O34: 2.2066219 | P34: 1.133865 | Q34: 1.7018852 | R34: 1.8680846 | S34: 1.4939001 | T34: 2.6477611 | U34: 1.7737203 | V34: 2.245721 | W34: 2.1120861 | X34: 1.535126 | Y34: 2.3055523 | Z34: 2.4922845 | AA34: 2.1591228 | AB34: 3.6056725 | AC34: 1.9691722 | AD34: 4.8581104 | AE34: 2.3745702 | AF34: 2.5136885 | AG34: 2.2057017 | AH34: 1.1334046 | AI34: 3.5973021 | AJ34: 1.4599952 | AK34: 1.5665931 | AL34: 4.0866102 | AM34: 1.7674948 | AN34: 1.6260662 | AO34: 1.7949494 | AP34: 2.2684061 | AQ34: 1.9381758 | AR34: 0.99416733 | AS34: 1.7834758 | AT34: 2.0230201 | AU34: 1.4561174 | AV34: 1.2795713 | AW34: 2.0962912 | AX34: 2.292711 | AY34: 0.79780971 | AZ34: 1.6421759 | BA34: 0.67098356 | BB34: 3.0809098 | BC34: 1.1422573 | BD34: 2.2889827
A35: 33 | B35: M_Berrs | C35: 01.d | D35: 01.25 | E35: Berries nes, market of | F35: tonnes | G35: 1.1500604 | H35: 1.6127295 | I35: 1.0839871 | J35: 2.8941578 | K35: 1.1319747 | L35: 1.6418214 | M35: 0.86186438 | N35: 1.3240512 | O35: 1.1904272 | P35: 2.3792011 | Q35: 1.384827 | R35: 1.0573426 | S35: 6.8120662 | T35: 0.62738012 | U35: 4.6231407 | V35: 0.78370663 | W35: 0.99051303 | X35: 0.87324068 | Y35: 0.83388338 | Z35: 4.8920586 | AA35: 0.84166378 | AB35: 0.99369308 | AC35: 1.2547952 | AD35: 0.56411712 | AE35: 0.91088682 | AF35: 0.54872527 | AH35: 3.8530672 | AI35: 1.0175338 | AJ35: 4.1378109 | AK35: 1.1888486 | AL35: 0.54827465 | AM35: 1.1159808 | AN35: 3.2097244 | AO35: 1.2547797 | AP35: 0.52191248 | AQ35: 0.5003955 | AR35: 0.97829475 | AS35: 4.3037493 | AT35: 1.2450159 | AU35: 0.86422866 | AV35: 0.77007515 | AX35: 0.81837929 | AY35: 0.74075002 | AZ35: 1.5992314 | BA35: 0.56413596 | BB35: 2.1430844 | BC35: 0.96681883 | BD35: 1.5873471
